import pytest
from unittest.mock import patch, Mock
from your_app import app, process_data_task

@pytest.fixture
def client():
	app.config['TESTING'] = True
	with app.test_client() as client:
		yield client

def test_process_data_task_handles_data_source_exception(client):
	# Mock the data source to raise an exception
	data_source_mock = Mock()
	data_source_mock.side_effect = Exception("Data source error")

	# Patch the data source and sink in the process_data_task function
	with patch('your_app.data_source', data_source_mock), patch('your_app.data_sink') as data_sink_mock:

		# Call the process_data_task function
		with pytest.raises(Exception, match="Data source error"):
			process_data_task()

		# Assert that data_sink was not called
		data_sink_mock.assert_not_called()

def test_process_data_task_handles_data_sink_exception(client):
	# Mock the data source to return valid data
	data_source_mock = Mock()
	data_source_mock.return_value = [{"key": 1, "value": "a"}]

	# Mock the data sink to raise an exception
	data_sink_mock = Mock()
	data_sink_mock.side_effect = Exception("Data sink error")

	# Patch the data source and sink
	with patch('your_app.data_source', data_source_mock), patch('your_app.data_sink', data_sink_mock):

		# Call the process_data_task function
		with pytest.raises(Exception, match="Data sink error"):
			process_data_task()

if __name__ == '__main__':
	pytest.main()
